2018-01-15 12:24:06,999 ERROR: Exception on /favicon.ico [GET] [in /Users/glowatsk/microwebsite/venv/lib/python3.6/site-packages/flask/app.py:1560]
Traceback (most recent call last):
  File "/Users/glowatsk/microwebsite/venv/lib/python3.6/site-packages/flask/app.py", line 1612, in full_dispatch_request
    rv = self.dispatch_request()
  File "/Users/glowatsk/microwebsite/venv/lib/python3.6/site-packages/flask/app.py", line 1590, in dispatch_request
    self.raise_routing_exception(req)
  File "/Users/glowatsk/microwebsite/venv/lib/python3.6/site-packages/flask/app.py", line 1573, in raise_routing_exception
    raise request.routing_exception
  File "/Users/glowatsk/microwebsite/venv/lib/python3.6/site-packages/flask/ctx.py", line 294, in match_request
    self.url_adapter.match(return_rule=True)
  File "/Users/glowatsk/microwebsite/venv/lib/python3.6/site-packages/werkzeug/routing.py", line 1581, in match
    raise NotFound()
werkzeug.exceptions.NotFound: 404 Not Found: The requested URL was not found on the server.  If you entered the URL manually please check your spelling and try again.

During handling of the above exception, another exception occurred:

Traceback (most recent call last):
  File "/Users/glowatsk/microwebsite/venv/lib/python3.6/site-packages/flask/app.py", line 1982, in wsgi_app
    response = self.full_dispatch_request()
  File "/Users/glowatsk/microwebsite/venv/lib/python3.6/site-packages/flask/app.py", line 1614, in full_dispatch_request
    rv = self.handle_user_exception(e)
  File "/Users/glowatsk/microwebsite/venv/lib/python3.6/site-packages/flask/app.py", line 1512, in handle_user_exception
    return self.handle_http_exception(e)
  File "/Users/glowatsk/microwebsite/venv/lib/python3.6/site-packages/flask/app.py", line 1471, in handle_http_exception
    return handler(e)
  File "/Users/glowatsk/microwebsite/app/errors.py", line 6, in not_found_error
    return render_template('404.html'), 404
  File "/Users/glowatsk/microwebsite/venv/lib/python3.6/site-packages/flask/templating.py", line 133, in render_template
    return _render(ctx.app.jinja_env.get_or_select_template(template_name_or_list),
  File "/Users/glowatsk/microwebsite/venv/lib/python3.6/site-packages/jinja2/environment.py", line 869, in get_or_select_template
    return self.get_template(template_name_or_list, parent, globals)
  File "/Users/glowatsk/microwebsite/venv/lib/python3.6/site-packages/jinja2/environment.py", line 830, in get_template
    return self._load_template(name, self.make_globals(globals))
  File "/Users/glowatsk/microwebsite/venv/lib/python3.6/site-packages/jinja2/environment.py", line 804, in _load_template
    template = self.loader.load(self, name, globals)
  File "/Users/glowatsk/microwebsite/venv/lib/python3.6/site-packages/jinja2/loaders.py", line 125, in load
    code = environment.compile(source, name, filename)
  File "/Users/glowatsk/microwebsite/venv/lib/python3.6/site-packages/jinja2/environment.py", line 591, in compile
    self.handle_exception(exc_info, source_hint=source_hint)
  File "/Users/glowatsk/microwebsite/venv/lib/python3.6/site-packages/jinja2/environment.py", line 780, in handle_exception
    reraise(exc_type, exc_value, tb)
  File "/Users/glowatsk/microwebsite/venv/lib/python3.6/site-packages/jinja2/_compat.py", line 37, in reraise
    raise value.with_traceback(tb)
  File "/Users/glowatsk/microwebsite/app/templates/404.html", line 6, in template
    {% end block %}
  File "/Users/glowatsk/microwebsite/venv/lib/python3.6/site-packages/jinja2/environment.py", line 497, in _parse
    return Parser(self, source, name, encode_filename(filename)).parse()
  File "/Users/glowatsk/microwebsite/venv/lib/python3.6/site-packages/jinja2/parser.py", line 901, in parse
    result = nodes.Template(self.subparse(), lineno=1)
  File "/Users/glowatsk/microwebsite/venv/lib/python3.6/site-packages/jinja2/parser.py", line 883, in subparse
    rv = self.parse_statement()
  File "/Users/glowatsk/microwebsite/venv/lib/python3.6/site-packages/jinja2/parser.py", line 130, in parse_statement
    return getattr(self, 'parse_' + self.stream.current.value)()
  File "/Users/glowatsk/microwebsite/venv/lib/python3.6/site-packages/jinja2/parser.py", line 268, in parse_block
    node.body = self.parse_statements(('name:endblock',), drop_needle=True)
  File "/Users/glowatsk/microwebsite/venv/lib/python3.6/site-packages/jinja2/parser.py", line 165, in parse_statements
    result = self.subparse(end_tokens)
  File "/Users/glowatsk/microwebsite/venv/lib/python3.6/site-packages/jinja2/parser.py", line 883, in subparse
    rv = self.parse_statement()
  File "/Users/glowatsk/microwebsite/venv/lib/python3.6/site-packages/jinja2/parser.py", line 144, in parse_statement
    self.fail_unknown_tag(token.value, token.lineno)
  File "/Users/glowatsk/microwebsite/venv/lib/python3.6/site-packages/jinja2/parser.py", line 97, in fail_unknown_tag
    return self._fail_ut_eof(name, self._end_token_stack, lineno)
  File "/Users/glowatsk/microwebsite/venv/lib/python3.6/site-packages/jinja2/parser.py", line 90, in _fail_ut_eof
    self.fail(' '.join(message), lineno)
  File "/Users/glowatsk/microwebsite/venv/lib/python3.6/site-packages/jinja2/parser.py", line 59, in fail
    raise exc(msg, lineno, self.name, self.filename)
jinja2.exceptions.TemplateSyntaxError: Encountered unknown tag 'end'. Jinja was looking for the following tags: 'endblock'. The innermost block that needs to be closed is 'block'.
2018-01-15 12:36:05,942 INFO: Microsite Setup [in /Users/glowatsk/microwebsite/app/__init__.py:45]
2018-01-15 12:36:21,418 INFO: Microsite Setup [in /Users/glowatsk/microwebsite/app/__init__.py:45]
2018-01-16 12:35:40,136 INFO: Microsite Setup [in /Users/glowatsk/microwebsite/app/__init__.py:45]
2018-01-16 12:36:06,754 INFO: Microsite Setup [in /Users/glowatsk/microwebsite/app/__init__.py:45]
2018-01-17 12:38:40,472 INFO: Microsite Setup [in /Users/glowatsk/microwebsite/app/__init__.py:45]
2018-01-17 12:38:45,666 ERROR: Exception on /index [GET] [in /Users/glowatsk/microwebsite/venv/lib/python3.6/site-packages/flask/app.py:1560]
Traceback (most recent call last):
  File "/Users/glowatsk/microwebsite/venv/lib/python3.6/site-packages/flask/app.py", line 1982, in wsgi_app
    response = self.full_dispatch_request()
  File "/Users/glowatsk/microwebsite/venv/lib/python3.6/site-packages/flask/app.py", line 1614, in full_dispatch_request
    rv = self.handle_user_exception(e)
  File "/Users/glowatsk/microwebsite/venv/lib/python3.6/site-packages/flask/app.py", line 1517, in handle_user_exception
    reraise(exc_type, exc_value, tb)
  File "/Users/glowatsk/microwebsite/venv/lib/python3.6/site-packages/flask/_compat.py", line 33, in reraise
    raise value
  File "/Users/glowatsk/microwebsite/venv/lib/python3.6/site-packages/flask/app.py", line 1612, in full_dispatch_request
    rv = self.dispatch_request()
  File "/Users/glowatsk/microwebsite/venv/lib/python3.6/site-packages/flask/app.py", line 1598, in dispatch_request
    return self.view_functions[rule.endpoint](**req.view_args)
  File "/Users/glowatsk/microwebsite/venv/lib/python3.6/site-packages/flask_login/utils.py", line 261, in decorated_view
    return func(*args, **kwargs)
  File "/Users/glowatsk/microwebsite/app/routes.py", line 29, in index
    posts = current_user.followed.posts().all()
AttributeError: 'AppenderBaseQuery' object has no attribute 'posts'
2018-01-17 12:40:44,744 ERROR: Exception on /index [GET] [in /Users/glowatsk/microwebsite/venv/lib/python3.6/site-packages/flask/app.py:1560]
Traceback (most recent call last):
  File "/Users/glowatsk/microwebsite/venv/lib/python3.6/site-packages/flask/app.py", line 1982, in wsgi_app
    response = self.full_dispatch_request()
  File "/Users/glowatsk/microwebsite/venv/lib/python3.6/site-packages/flask/app.py", line 1614, in full_dispatch_request
    rv = self.handle_user_exception(e)
  File "/Users/glowatsk/microwebsite/venv/lib/python3.6/site-packages/flask/app.py", line 1517, in handle_user_exception
    reraise(exc_type, exc_value, tb)
  File "/Users/glowatsk/microwebsite/venv/lib/python3.6/site-packages/flask/_compat.py", line 33, in reraise
    raise value
  File "/Users/glowatsk/microwebsite/venv/lib/python3.6/site-packages/flask/app.py", line 1612, in full_dispatch_request
    rv = self.dispatch_request()
  File "/Users/glowatsk/microwebsite/venv/lib/python3.6/site-packages/flask/app.py", line 1598, in dispatch_request
    return self.view_functions[rule.endpoint](**req.view_args)
  File "/Users/glowatsk/microwebsite/venv/lib/python3.6/site-packages/flask_login/utils.py", line 261, in decorated_view
    return func(*args, **kwargs)
  File "/Users/glowatsk/microwebsite/app/routes.py", line 29, in index
    posts = current_user.followed.posts().all()
AttributeError: 'AppenderBaseQuery' object has no attribute 'posts'
