2018-01-17 12:44:41,186 ERROR: Exception on /register [POST] [in /Users/glowatsk/microwebsite/venv/lib/python3.6/site-packages/flask/app.py:1560]
Traceback (most recent call last):
  File "/Users/glowatsk/microwebsite/venv/lib/python3.6/site-packages/sqlalchemy/engine/base.py", line 1193, in _execute_context
    context)
  File "/Users/glowatsk/microwebsite/venv/lib/python3.6/site-packages/sqlalchemy/engine/default.py", line 507, in do_execute
    cursor.execute(statement, parameters)
sqlite3.IntegrityError: UNIQUE constraint failed: user.username

The above exception was the direct cause of the following exception:

Traceback (most recent call last):
  File "/Users/glowatsk/microwebsite/venv/lib/python3.6/site-packages/flask/app.py", line 1982, in wsgi_app
    response = self.full_dispatch_request()
  File "/Users/glowatsk/microwebsite/venv/lib/python3.6/site-packages/flask/app.py", line 1614, in full_dispatch_request
    rv = self.handle_user_exception(e)
  File "/Users/glowatsk/microwebsite/venv/lib/python3.6/site-packages/flask/app.py", line 1517, in handle_user_exception
    reraise(exc_type, exc_value, tb)
  File "/Users/glowatsk/microwebsite/venv/lib/python3.6/site-packages/flask/_compat.py", line 33, in reraise
    raise value
  File "/Users/glowatsk/microwebsite/venv/lib/python3.6/site-packages/flask/app.py", line 1612, in full_dispatch_request
    rv = self.dispatch_request()
  File "/Users/glowatsk/microwebsite/venv/lib/python3.6/site-packages/flask/app.py", line 1598, in dispatch_request
    return self.view_functions[rule.endpoint](**req.view_args)
  File "/Users/glowatsk/microwebsite/app/routes.py", line 65, in register
    db.session.commit()
  File "/Users/glowatsk/microwebsite/venv/lib/python3.6/site-packages/sqlalchemy/orm/scoping.py", line 153, in do
    return getattr(self.registry(), name)(*args, **kwargs)
  File "/Users/glowatsk/microwebsite/venv/lib/python3.6/site-packages/sqlalchemy/orm/session.py", line 937, in commit
    self.transaction.commit()
  File "/Users/glowatsk/microwebsite/venv/lib/python3.6/site-packages/sqlalchemy/orm/session.py", line 461, in commit
    self._prepare_impl()
  File "/Users/glowatsk/microwebsite/venv/lib/python3.6/site-packages/sqlalchemy/orm/session.py", line 441, in _prepare_impl
    self.session.flush()
  File "/Users/glowatsk/microwebsite/venv/lib/python3.6/site-packages/sqlalchemy/orm/session.py", line 2237, in flush
    self._flush(objects)
  File "/Users/glowatsk/microwebsite/venv/lib/python3.6/site-packages/sqlalchemy/orm/session.py", line 2363, in _flush
    transaction.rollback(_capture_exception=True)
  File "/Users/glowatsk/microwebsite/venv/lib/python3.6/site-packages/sqlalchemy/util/langhelpers.py", line 66, in __exit__
    compat.reraise(exc_type, exc_value, exc_tb)
  File "/Users/glowatsk/microwebsite/venv/lib/python3.6/site-packages/sqlalchemy/util/compat.py", line 187, in reraise
    raise value
  File "/Users/glowatsk/microwebsite/venv/lib/python3.6/site-packages/sqlalchemy/orm/session.py", line 2327, in _flush
    flush_context.execute()
  File "/Users/glowatsk/microwebsite/venv/lib/python3.6/site-packages/sqlalchemy/orm/unitofwork.py", line 391, in execute
    rec.execute(self)
  File "/Users/glowatsk/microwebsite/venv/lib/python3.6/site-packages/sqlalchemy/orm/unitofwork.py", line 556, in execute
    uow
  File "/Users/glowatsk/microwebsite/venv/lib/python3.6/site-packages/sqlalchemy/orm/persistence.py", line 181, in save_obj
    mapper, table, insert)
  File "/Users/glowatsk/microwebsite/venv/lib/python3.6/site-packages/sqlalchemy/orm/persistence.py", line 866, in _emit_insert_statements
    execute(statement, params)
  File "/Users/glowatsk/microwebsite/venv/lib/python3.6/site-packages/sqlalchemy/engine/base.py", line 948, in execute
    return meth(self, multiparams, params)
  File "/Users/glowatsk/microwebsite/venv/lib/python3.6/site-packages/sqlalchemy/sql/elements.py", line 269, in _execute_on_connection
    return connection._execute_clauseelement(self, multiparams, params)
  File "/Users/glowatsk/microwebsite/venv/lib/python3.6/site-packages/sqlalchemy/engine/base.py", line 1060, in _execute_clauseelement
    compiled_sql, distilled_params
  File "/Users/glowatsk/microwebsite/venv/lib/python3.6/site-packages/sqlalchemy/engine/base.py", line 1200, in _execute_context
    context)
  File "/Users/glowatsk/microwebsite/venv/lib/python3.6/site-packages/sqlalchemy/engine/base.py", line 1413, in _handle_dbapi_exception
    exc_info
  File "/Users/glowatsk/microwebsite/venv/lib/python3.6/site-packages/sqlalchemy/util/compat.py", line 203, in raise_from_cause
    reraise(type(exception), exception, tb=exc_tb, cause=cause)
  File "/Users/glowatsk/microwebsite/venv/lib/python3.6/site-packages/sqlalchemy/util/compat.py", line 186, in reraise
    raise value.with_traceback(tb)
  File "/Users/glowatsk/microwebsite/venv/lib/python3.6/site-packages/sqlalchemy/engine/base.py", line 1193, in _execute_context
    context)
  File "/Users/glowatsk/microwebsite/venv/lib/python3.6/site-packages/sqlalchemy/engine/default.py", line 507, in do_execute
    cursor.execute(statement, parameters)
sqlalchemy.exc.IntegrityError: (sqlite3.IntegrityError) UNIQUE constraint failed: user.username [SQL: 'INSERT INTO user (username, email, password_hash, about_me, last_seen) VALUES (?, ?, ?, ?, ?)'] [parameters: ('BrandonG', 'glowatsk@gmail.com', 'pbkdf2:sha256:50000$MkfPubDd$38cc00776d7f28fe68cffd22e36dcfa2dc2242f35d4231da654b27d2f2d71e88', None, '2018-01-17 19:44:41.186192')] (Background on this error at: http://sqlalche.me/e/gkpj)
2018-01-17 12:45:52,338 ERROR: Exception on /index [GET] [in /Users/glowatsk/microwebsite/venv/lib/python3.6/site-packages/flask/app.py:1560]
Traceback (most recent call last):
  File "/Users/glowatsk/microwebsite/venv/lib/python3.6/site-packages/flask/app.py", line 1982, in wsgi_app
    response = self.full_dispatch_request()
  File "/Users/glowatsk/microwebsite/venv/lib/python3.6/site-packages/flask/app.py", line 1614, in full_dispatch_request
    rv = self.handle_user_exception(e)
  File "/Users/glowatsk/microwebsite/venv/lib/python3.6/site-packages/flask/app.py", line 1517, in handle_user_exception
    reraise(exc_type, exc_value, tb)
  File "/Users/glowatsk/microwebsite/venv/lib/python3.6/site-packages/flask/_compat.py", line 33, in reraise
    raise value
  File "/Users/glowatsk/microwebsite/venv/lib/python3.6/site-packages/flask/app.py", line 1612, in full_dispatch_request
    rv = self.dispatch_request()
  File "/Users/glowatsk/microwebsite/venv/lib/python3.6/site-packages/flask/app.py", line 1598, in dispatch_request
    return self.view_functions[rule.endpoint](**req.view_args)
  File "/Users/glowatsk/microwebsite/venv/lib/python3.6/site-packages/flask_login/utils.py", line 261, in decorated_view
    return func(*args, **kwargs)
  File "/Users/glowatsk/microwebsite/app/routes.py", line 29, in index
    posts = current_user.followed.posts().all()
AttributeError: 'AppenderBaseQuery' object has no attribute 'posts'
